<robot name="blocks">

  <link name="stand1">
    <inertial>
      <origin xyz="0 0 0.25" />
      <mass value="0.1" />
      <inertia  ixx="0.00003375" ixy="0.0"  ixz="0.0"  iyy="0.00003375"  iyz="0.0"  izz="0.00003375" />
    </inertial>

    <visual>
      <origin rpy="0 0 0" xyz="0 0 0.25"/>
      <geometry>
        <box size="0.045 0.045 0.50" />
      </geometry>
      <material name="red">
        <color rgba="0.4 0.4 1.0 1.0"/>
      </material>
    </visual>

    <collision>
      <origin xyz="0 0 0.25"/>
      <geometry>
        <box size="0.045 0.045 0.50" />
      </geometry>
    </collision>

  </link>


  <link name="block">

      <inertial>
        <origin xyz="0 0 0.05" />
        <mass value="1" />
        <inertia ixx="0.10" ixy="0.0" ixz="0.0" iyy="0.10" iyz="0.0" izz="0.10"/>
      </inertial>

      <visual>
        <origin xyz="0 0 0.05"/>
        <geometry>
          <box size="0.45 0.45 0.10" />
        </geometry>
        <material name="red">
          <color rgba="0.4 0.4 1.0 1.0"/>
        </material>
      </visual>

      <collision>
        <origin xyz="0 0 0.05"/>
        <geometry>
          <box size="0.45 0.45 0.10" />
        </geometry>
      </collision>

  </link>


  <joint name="cart_to_pole" type="revolute">
    <axis xyz="0 1 0"/>
    <origin xyz="0.0 0.0 0"/>
    <parent link="block"/>
    <child link="stand1"/>
    <limit upper="0.01" lower="-0.1757" velocity="2.0"/>
  </joint>


</robot>
