<?xml version="1.0"?>
<robot name="physics">

  

  <link name="cart">
    <visual>
      <geometry>
        <box size="0.1 0.1 0.03"/>
      </geometry>
      <origin xyz="0 0 0"/>
      <material name="blue">
        <color rgba="0 0 .8 1"/>
      </material>
    </visual>
    <collision>
      <geometry>
          <box size="0.1 0.1 0.03"/>
      </geometry>
      <origin xyz="0 0 0"/>
    </collision>
    <inertial>
      <mass value="1000"/>
      <inertia ixx="1.0" ixy="0.0" ixz="0.0" iyy="1.0" iyz="0.0" izz="1.0"/>
    </inertial>
  </link>


  <link name="pole">
    <visual>
      <geometry>
        <box size="0.01 0.01 0.2"/>	
      </geometry>
      <origin rpy="0 0 0" xyz="0 0 0.1"/>
      <material name="white">
        <color rgba="1 1 1 1"/>
      </material>
    </visual>
    <inertial>
    <origin xyz="0 0 0.1"/>
      <mass value="1"/>
      <inertia ixx="1.0" ixy="0.0" ixz="0.0" iyy="1.0" iyz="0.0" izz="1.0"/>
    </inertial>
     <collision>
      <geometry>
        <box size="0.01 0.01 0.2"/>	
      </geometry>
      <origin rpy="0 0 0" xyz="0 0 0.1"/>
    </collision>
  </link>

  <link name="pole2">
    <visual>
      <geometry>
        <box size="0.01 0.01 0.2"/>	
      </geometry>
      <origin rpy="0 0 0" xyz="0 0 0.1"/>
      <material name="white">
        <color rgba="1 1 1 1"/>
      </material>
    </visual>
    <inertial>
    <origin xyz="0 0 0.1"/>
      <mass value="1"/>
      <inertia ixx="1.0" ixy="0.0" ixz="0.0" iyy="1.0" iyz="0.0" izz="1.0"/>
    </inertial>
     <collision>
      <geometry>
        <box size="0.01 0.01 0.2"/>	
      </geometry>
      <origin rpy="0 0 0" xyz="0 0 0.1"/>
    </collision>
  </link>


  <link name="pole3">
    <visual>
      <geometry>
        <box size="0.01 0.01 0.2"/>	
      </geometry>
      <origin rpy="0 0 0" xyz="0 0 0.1"/>
      <material name="white">
        <color rgba="1 1 1 1"/>
      </material>
    </visual>
    <inertial>
    <origin xyz="0 0 0.1"/>
      <mass value="1"/>
      <inertia ixx="1.0" ixy="0.0" ixz="0.0" iyy="1.0" iyz="0.0" izz="1.0"/>
    </inertial>
     <collision>
      <geometry>
        <box size="0.01 0.01 0.2"/>	
      </geometry>
      <origin rpy="0 0 0" xyz="0 0 0.1"/>
    </collision>
  </link>

  <link name="pole4">
    <visual>
      <geometry>
        <box size="0.01 0.01 0.2"/>	
      </geometry>
      <origin rpy="0 0 0" xyz="0 0 0.1"/>
      <material name="white">
        <color rgba="1 1 1 1"/>
      </material>
    </visual>
    <inertial>
    <origin xyz="0 0 0.1"/>
      <mass value="1"/>
      <inertia ixx="1.0" ixy="0.0" ixz="0.0" iyy="1.0" iyz="0.0" izz="1.0"/>
    </inertial>
     <collision>
      <geometry>
        <box size="0.01 0.01 0.2"/>	
      </geometry>
      <origin rpy="0 0 0" xyz="0 0 0.1"/>
    </collision>
  </link>



  <joint name="cart_to_pole" type="revolute">
    <axis xyz="0 1 0"/>
    <origin xyz="0.045 0.045 0.02"/>
    <parent link="cart"/>
    <child link="pole"/>
    <limit upper="0.2" lower="-0.1757" velocity="2.0"/>
  </joint>

  <joint name="cart_to_pole2" type="revolute">
    <axis xyz="0 1 0"/>
    <origin xyz="-0.045 -0.045 0.02"/>
    <parent link="cart"/>
    <child link="pole2"/>
    <limit upper="0.2" lower="-0.1757" velocity="2.0"/>
  </joint>

  <joint name="cart_to_pole3" type="revolute">
    <axis xyz="0 1 0"/>
    <origin xyz="0.045 -0.045 0.02"/>
    <parent link="cart"/>
    <child link="pole3"/>
    <limit upper="0.2" lower="-0.1757" velocity="2.0"/>
  </joint>

  <joint name="cart_to_pole4" type="revolute">
    <axis xyz="0 1 0"/>
    <origin xyz="-0.045 0.045 0.02"/>
    <parent link="cart"/>
    <child link="pole4"/>
    <limit upper="0.2" lower="-0.1757" velocity="2.0"/>
  </joint>
  
</robot>