<robot name="blocks">

  <link name="world">
    <inertial>
      <mass value="0"/>
      <inertia ixx="0" ixy="0" ixz="0"
                  iyx="0" iyy="0" iyz="0"
                  izx="0" izy="0" izz="0"/>
    </inertial>
  </link>

  <link name="stand">
    <inertial>
      <origin xyz="0 0 0" />
      <mass value="0.1" />
      <inertia  ixx="0.00003375" ixy="0.0"  ixz="0.0"  iyy="0.00003375"  iyz="0.0"  izz="0.00003375" />
    </inertial>

    <visual>
      <origin xyz="0 0 0"/>
      <geometry>
        <box size="0.085 0.085 0.50" />
      </geometry>
      <material name="red">
        <color rgba="0.4 0.4 1.0 1.0"/>
      </material>
    </visual>

    <collision>
      <origin xyz="0 0 0"/>
      <geometry>
        <box size="0.085 0.085 0.50" />
      </geometry>
    </collision>

  </link>


  <link name="block">

      <inertial>
        <origin xyz="0 0 0" />
        <mass value="0.1" />
        <inertia  ixx="0.00003375" ixy="0.0"  ixz="0.0"  iyy="0.00003375"  iyz="0.0"  izz="0.00003375" />
      </inertial>

      <visual>
        <origin xyz="0 0 0"/>
        <geometry>
          <box size="0.85 0.85 0.050" />
        </geometry>
        <material name="red">
          <color rgba="0.4 0.4 1.0 1.0"/>
        </material>
      </visual>

      <collision>
        <origin xyz="0 0 0"/>
        <geometry>
          <box size="0.85 0.85 0.050" />
        </geometry>
      </collision>

  </link>



  <!-- connect arm to world -->
  <joint name="world_arm_joint" type="fixed">
    <parent link="world"/>
    <child link="stand"/>
    <axis xyz="0 0 0"/>
    <origin rpy="0.0 0.0 0.0" xyz="0 0 0"/>
  </joint>

  <joint name="prismatic_joint" type="prismatic">
    <parent link="stand"/>
    <child link="block"/>
    <axis xyz="0 0 1"/>
    <limit upper="1000" lower="-0.8757" velocity="2.0"/>
    <origin rpy="0.0 0.0 0" xyz="0.425 0.425 0"/>
  </joint>


</robot>
